rank=00 L00: Traceback (most recent call last):
rank=00 L01:   File "./job.py", line 20, in <module>
rank=00 L02:     relax = LBFGS(atoms=atoms, logfile='final_opt.log', trajectory='final_opt.traj')
rank=00 L03:   File "/uls/7/gpaw-20.1.0/lib/python3.8/site-packages/ase-3.20.1-py3.8.egg/ase/optimize/lbfgs.py", line 65, in __init__
rank=00 L04:     Optimizer.__init__(self, atoms, restart, logfile, trajectory, master,
rank=00 L05:   File "/uls/7/gpaw-20.1.0/lib/python3.8/site-packages/ase-3.20.1-py3.8.egg/ase/optimize/optimize.py", line 240, in __init__
rank=00 L06:     self.set_force_consistent()
rank=00 L07:   File "/uls/7/gpaw-20.1.0/lib/python3.8/site-packages/ase-3.20.1-py3.8.egg/ase/optimize/optimize.py", line 324, in set_force_consistent
rank=00 L08:     self.atoms.get_potential_energy(force_consistent=True)
rank=00 L09:   File "/uls/7/gpaw-20.1.0/lib/python3.8/site-packages/ase-3.20.1-py3.8.egg/ase/atoms.py", line 730, in get_potential_energy
rank=00 L10:     energy = self._calc.get_potential_energy(
rank=00 L11:   File "/uls/7/gpaw-20.1.0/lib/python3.8/site-packages/ase-3.20.1-py3.8.egg/ase/calculators/calculator.py", line 682, in get_potential_energy
rank=00 L12:     energy = self.get_property('energy', atoms)
rank=00 L13:   File "/uls/7/gpaw-20.1.0/lib/python3.8/site-packages/ase-3.20.1-py3.8.egg/ase/calculators/calculator.py", line 738, in get_property
rank=00 L14:     self.calculate(atoms, [name], system_changes)
rank=00 L15:   File "/uls/7/gpaw-20.1.0/lib/python3.8/site-packages/gpaw-20.1.0-py3.8-linux-x86_64.egg/gpaw/calculator.py", line 288, in calculate
rank=00 L16:     self.initialize(atoms)
rank=00 L17:   File "/uls/7/gpaw-20.1.0/lib/python3.8/site-packages/gpaw-20.1.0-py3.8-linux-x86_64.egg/gpaw/calculator.py", line 726, in initialize
rank=00 L18:     xc.initialize(self.density, self.hamiltonian, self.wfs,
rank=00 L19:   File "/uls/7/gpaw-20.1.0/lib/python3.8/site-packages/gpaw-20.1.0-py3.8-linux-x86_64.egg/gpaw/xc/libvdwxc.py", line 414, in initialize
rank=00 L20:     raise ValueError('You are using libvdwxc with only '
rank=00 L21: ValueError: You are using libvdwxc with only 4 out of 32 available cores in a non-small calculation (80 x 64 x 320 points).  This is not a crime but is likely silly and therefore triggers an error.  Please use parallel={'augment_grids': True} or complain to the developers.  You can also disable this error by passing accept_partial_decomposition=True to the libvdwxc functional object, but be careful to use good domain decomposition.
GPAW CLEANUP (node 0): <class 'ValueError'> occurred.  Calling MPI_Abort!
rank=08 L00: Traceback (most recent call last):
rank=08 L01:   File "./job.py", line 20, in <module>
rank=08 L02:     relax = LBFGS(atoms=atoms, logfile='final_opt.log', trajectory='final_opt.traj')
rank=08 L03:   File "/uls/7/gpaw-20.1.0/lib/python3.8/site-packages/ase-3.20.1-py3.8.egg/ase/optimize/lbfgs.py", line 65, in __init__
rank=08 L04:     Optimizer.__init__(self, atoms, restart, logfile, trajectory, master,
rank=08 L05:   File "/uls/7/gpaw-20.1.0/lib/python3.8/site-packages/ase-3.20.1-py3.8.egg/ase/optimize/optimize.py", line 240, in __init__
rank=08 L06:     self.set_force_consistent()
rank=08 L07:   File "/uls/7/gpaw-20.1.0/lib/python3.8/site-packages/ase-3.20.1-py3.8.egg/ase/optimize/optimize.py", line 324, in set_force_consistent
rank=08 L08:     self.atoms.get_potential_energy(force_consistent=True)
rank=08 L09:   File "/uls/7/gpaw-20.1.0/lib/python3.8/site-packages/ase-3.20.1-py3.8.egg/ase/atoms.py", line 730, in get_potential_energy
rank=08 L10:     energy = self._calc.get_potential_energy(
rank=08 L11:   File "/uls/7/gpaw-20.1.0/lib/python3.8/site-packages/ase-3.20.1-py3.8.egg/ase/calculators/calculator.py", line 682, in get_potential_energy
rank=08 L12:     energy = self.get_property('energy', atoms)
rank=08 L13:   File "/uls/7/gpaw-20.1.0/lib/python3.8/site-packages/ase-3.20.1-py3.8.egg/ase/calculators/calculator.py", line 738, in get_property
rank=08 L14:     self.calculate(atoms, [name], system_changes)
rank=08 L15:   File "/uls/7/gpaw-20.1.0/lib/python3.8/site-packages/gpaw-20.1.0-py3.8-linux-x86_64.egg/gpaw/calculator.py", line 288, in calculate
rank=08 L16:     self.initialize(atoms)
rank=08 L17:   File "/uls/7/gpaw-20.1.0/lib/python3.8/site-packages/gpaw-20.1.0-py3.8-linux-x86_64.egg/gpaw/calculator.py", line 726, in initialize
rank=08 L18:     xc.initialize(self.density, self.hamiltonian, self.wfs,
rank=08 L19:   File "/uls/7/gpaw-20.1.0/lib/python3.8/site-packages/gpaw-20.1.0-py3.8-linux-x86_64.egg/gpaw/xc/libvdwxc.py", line 414, in initialize
rank=08 L20:     raise ValueError('You are using libvdwxc with only '
rank=08 L21: ValueError: You are using libvdwxc with only 4 out of 32 available cores in a non-small calculation (80 x 64 x 320 points).  This is not a crime but is likely silly and therefore triggers an error.  Please use parallel={'augment_grids': True} or complain to the developers.  You can also disable this error by passing accept_partial_decomposition=True to the libvdwxc functional object, but be careful to use good domain decomposition.
GPAW CLEANUP (node 8): <class 'ValueError'> occurred.  Calling MPI_Abort!
rank=02 L00: Traceback (most recent call last):
rank=02 L01:   File "./job.py", line 20, in <module>
rank=02 L02:     relax = LBFGS(atoms=atoms, logfile='final_opt.log', trajectory='final_opt.traj')
rank=02 L03:   File "/uls/7/gpaw-20.1.0/lib/python3.8/site-packages/ase-3.20.1-py3.8.egg/ase/optimize/lbfgs.py", line 65, in __init__
rank=02 L04:     Optimizer.__init__(self, atoms, restart, logfile, trajectory, master,
rank=02 L05:   File "/uls/7/gpaw-20.1.0/lib/python3.8/site-packages/ase-3.20.1-py3.8.egg/ase/optimize/optimize.py", line 240, in __init__
rank=02 L06:     self.set_force_consistent()
rank=02 L07:   File "/uls/7/gpaw-20.1.0/lib/python3.8/site-packages/ase-3.20.1-py3.8.egg/ase/optimize/optimize.py", line 324, in set_force_consistent
rank=02 L08:     self.atoms.get_potential_energy(force_consistent=True)
rank=02 L09:   File "/uls/7/gpaw-20.1.0/lib/python3.8/site-packages/ase-3.20.1-py3.8.egg/ase/atoms.py", line 730, in get_potential_energy
rank=02 L10:     energy = self._calc.get_potential_energy(
rank=02 L11:   File "/uls/7/gpaw-20.1.0/lib/python3.8/site-packages/ase-3.20.1-py3.8.egg/ase/calculators/calculator.py", line 682, in get_potential_energy
rank=02 L12:     energy = self.get_property('energy', atoms)
rank=02 L13:   File "/uls/7/gpaw-20.1.0/lib/python3.8/site-packages/ase-3.20.1-py3.8.egg/ase/calculators/calculator.py", line 738, in get_property
rank=02 L14:     self.calculate(atoms, [name], system_changes)
rank=02 L15:   File "/uls/7/gpaw-20.1.0/lib/python3.8/site-packages/gpaw-20.1.0-py3.8-linux-x86_64.egg/gpaw/calculator.py", line 288, in calculate
rank=02 L16:     self.initialize(atoms)
rank=02 L17:   File "/uls/7/gpaw-20.1.0/lib/python3.8/site-packages/gpaw-20.1.0-py3.8-linux-x86_64.egg/gpaw/calculator.py", line 726, in initialize
rank=02 L18:     xc.initialize(self.density, self.hamiltonian, self.wfs,
rank=02 L19:   File "/uls/7/gpaw-20.1.0/lib/python3.8/site-packages/gpaw-20.1.0-py3.8-linux-x86_64.egg/gpaw/xc/libvdwxc.py", line 414, in initialize
rank=02 L20:     raise ValueError('You are using libvdwxc with only '
rank=02 L21: ValueError: You are using libvdwxc with only 4 out of 32 available cores in a non-small calculation (80 x 64 x 320 points).  This is not a crime but is likely silly and therefore triggers an error.  Please use parallel={'augment_grids': True} or complain to the developers.  You can also disable this error by passing accept_partial_decomposition=True to the libvdwxc functional object, but be careful to use good domain decomposition.
GPAW CLEANUP (node 2): <class 'ValueError'> occurred.  Calling MPI_Abort!
rank=04 L00: Traceback (most recent call last):
rank=04 L01:   File "./job.py", line 20, in <module>
rank=04 L02:     relax = LBFGS(atoms=atoms, logfile='final_opt.log', trajectory='final_opt.traj')
rank=04 L03:   File "/uls/7/gpaw-20.1.0/lib/python3.8/site-packages/ase-3.20.1-py3.8.egg/ase/optimize/lbfgs.py", line 65, in __init__
rank=04 L04:     Optimizer.__init__(self, atoms, restart, logfile, trajectory, master,
rank=04 L05:   File "/uls/7/gpaw-20.1.0/lib/python3.8/site-packages/ase-3.20.1-py3.8.egg/ase/optimize/optimize.py", line 240, in __init__
rank=04 L06:     self.set_force_consistent()
rank=04 L07:   File "/uls/7/gpaw-20.1.0/lib/python3.8/site-packages/ase-3.20.1-py3.8.egg/ase/optimize/optimize.py", line 324, in set_force_consistent
rank=04 L08:     self.atoms.get_potential_energy(force_consistent=True)
rank=04 L09:   File "/uls/7/gpaw-20.1.0/lib/python3.8/site-packages/ase-3.20.1-py3.8.egg/ase/atoms.py", line 730, in get_potential_energy
rank=04 L10:     energy = self._calc.get_potential_energy(
rank=04 L11:   File "/uls/7/gpaw-20.1.0/lib/python3.8/site-packages/ase-3.20.1-py3.8.egg/ase/calculators/calculator.py", line 682, in get_potential_energy
rank=04 L12:     energy = self.get_property('energy', atoms)
rank=04 L13:   File "/uls/7/gpaw-20.1.0/lib/python3.8/site-packages/ase-3.20.1-py3.8.egg/ase/calculators/calculator.py", line 738, in get_property
rank=04 L14:     self.calculate(atoms, [name], system_changes)
rank=04 L15:   File "/uls/7/gpaw-20.1.0/lib/python3.8/site-packages/gpaw-20.1.0-py3.8-linux-x86_64.egg/gpaw/calculator.py", line 288, in calculate
rank=04 L16:     self.initialize(atoms)
rank=04 L17:   File "/uls/7/gpaw-20.1.0/lib/python3.8/site-packages/gpaw-20.1.0-py3.8-linux-x86_64.egg/gpaw/calculator.py", line 726, in initialize
rank=04 L18:     xc.initialize(self.density, self.hamiltonian, self.wfs,
rank=04 L19:   File "/uls/7/gpaw-20.1.0/lib/python3.8/site-packages/gpaw-20.1.0-py3.8-linux-x86_64.egg/gpaw/xc/libvdwxc.py", line 414, in initialize
rank=04 L20:     raise ValueError('You are using libvdwxc with only '
rank=04 L21: ValueError: You are using libvdwxc with only 4 out of 32 available cores in a non-small calculation (80 x 64 x 320 points).  This is not a crime but is likely silly and therefore triggers an error.  Please use parallel={'augment_grids': True} or complain to the developers.  You can also disable this error by passing accept_partial_decomposition=True to the libvdwxc functional object, but be careful to use good domain decomposition.
GPAW CLEANUP (node 4): <class 'ValueError'> occurred.  Calling MPI_Abort!
rank=06 L00: Traceback (most recent call last):
rank=06 L01:   File "./job.py", line 20, in <module>
rank=06 L02:     relax = LBFGS(atoms=atoms, logfile='final_opt.log', trajectory='final_opt.traj')
rank=06 L03:   File "/uls/7/gpaw-20.1.0/lib/python3.8/site-packages/ase-3.20.1-py3.8.egg/ase/optimize/lbfgs.py", line 65, in __init__
rank=06 L04:     Optimizer.__init__(self, atoms, restart, logfile, trajectory, master,
rank=06 L05:   File "/uls/7/gpaw-20.1.0/lib/python3.8/site-packages/ase-3.20.1-py3.8.egg/ase/optimize/optimize.py", line 240, in __init__
rank=06 L06:     self.set_force_consistent()
rank=06 L07:   File "/uls/7/gpaw-20.1.0/lib/python3.8/site-packages/ase-3.20.1-py3.8.egg/ase/optimize/optimize.py", line 324, in set_force_consistent
rank=06 L08:     self.atoms.get_potential_energy(force_consistent=True)
rank=06 L09:   File "/uls/7/gpaw-20.1.0/lib/python3.8/site-packages/ase-3.20.1-py3.8.egg/ase/atoms.py", line 730, in get_potential_energy
rank=06 L10:     energy = self._calc.get_potential_energy(
rank=06 L11:   File "/uls/7/gpaw-20.1.0/lib/python3.8/site-packages/ase-3.20.1-py3.8.egg/ase/calculators/calculator.py", line 682, in get_potential_energy
rank=06 L12:     energy = self.get_property('energy', atoms)
rank=06 L13:   File "/uls/7/gpaw-20.1.0/lib/python3.8/site-packages/ase-3.20.1-py3.8.egg/ase/calculators/calculator.py", line 738, in get_property
rank=06 L14:     self.calculate(atoms, [name], system_changes)
rank=06 L15:   File "/uls/7/gpaw-20.1.0/lib/python3.8/site-packages/gpaw-20.1.0-py3.8-linux-x86_64.egg/gpaw/calculator.py", line 288, in calculate
rank=06 L16:     self.initialize(atoms)
rank=06 L17:   File "/uls/7/gpaw-20.1.0/lib/python3.8/site-packages/gpaw-20.1.0-py3.8-linux-x86_64.egg/gpaw/calculator.py", line 726, in initialize
rank=06 L18:     xc.initialize(self.density, self.hamiltonian, self.wfs,
rank=06 L19:   File "/uls/7/gpaw-20.1.0/lib/python3.8/site-packages/gpaw-20.1.0-py3.8-linux-x86_64.egg/gpaw/xc/libvdwxc.py", line 414, in initialize
rank=06 L20:     raise ValueError('You are using libvdwxc with only '
rank=06 L21: ValueError: You are using libvdwxc with only 4 out of 32 available cores in a non-small calculation (80 x 64 x 320 points).  This is not a crime but is likely silly and therefore triggers an error.  Please use parallel={'augment_grids': True} or complain to the developers.  You can also disable this error by passing accept_partial_decomposition=True to the libvdwxc functional object, but be careful to use good domain decomposition.
GPAW CLEANUP (node 6): <class 'ValueError'> occurred.  Calling MPI_Abort!
rank=10 L00: Traceback (most recent call last):
rank=10 L01:   File "./job.py", line 20, in <module>
rank=10 L02:     relax = LBFGS(atoms=atoms, logfile='final_opt.log', trajectory='final_opt.traj')
rank=10 L03:   File "/uls/7/gpaw-20.1.0/lib/python3.8/site-packages/ase-3.20.1-py3.8.egg/ase/optimize/lbfgs.py", line 65, in __init__
rank=10 L04:     Optimizer.__init__(self, atoms, restart, logfile, trajectory, master,
rank=10 L05:   File "/uls/7/gpaw-20.1.0/lib/python3.8/site-packages/ase-3.20.1-py3.8.egg/ase/optimize/optimize.py", line 240, in __init__
rank=10 L06:     self.set_force_consistent()
rank=10 L07:   File "/uls/7/gpaw-20.1.0/lib/python3.8/site-packages/ase-3.20.1-py3.8.egg/ase/optimize/optimize.py", line 324, in set_force_consistent
rank=10 L08:     self.atoms.get_potential_energy(force_consistent=True)
rank=10 L09:   File "/uls/7/gpaw-20.1.0/lib/python3.8/site-packages/ase-3.20.1-py3.8.egg/ase/atoms.py", line 730, in get_potential_energy
rank=10 L10:     energy = self._calc.get_potential_energy(
rank=10 L11:   File "/uls/7/gpaw-20.1.0/lib/python3.8/site-packages/ase-3.20.1-py3.8.egg/ase/calculators/calculator.py", line 682, in get_potential_energy
rank=10 L12:     energy = self.get_property('energy', atoms)
rank=10 L13:   File "/uls/7/gpaw-20.1.0/lib/python3.8/site-packages/ase-3.20.1-py3.8.egg/ase/calculators/calculator.py", line 738, in get_property
rank=10 L14:     self.calculate(atoms, [name], system_changes)
rank=10 L15:   File "/uls/7/gpaw-20.1.0/lib/python3.8/site-packages/gpaw-20.1.0-py3.8-linux-x86_64.egg/gpaw/calculator.py", line 288, in calculate
rank=10 L16:     self.initialize(atoms)
rank=10 L17:   File "/uls/7/gpaw-20.1.0/lib/python3.8/site-packages/gpaw-20.1.0-py3.8-linux-x86_64.egg/gpaw/calculator.py", line 726, in initialize
rank=10 L18:     xc.initialize(self.density, self.hamiltonian, self.wfs,
rank=10 L19:   File "/uls/7/gpaw-20.1.0/lib/python3.8/site-packages/gpaw-20.1.0-py3.8-linux-x86_64.egg/gpaw/xc/libvdwxc.py", line 414, in initialize
rank=10 L20:     raise ValueError('You are using libvdwxc with only '
rank=10 L21: ValueError: You are using libvdwxc with only 4 out of 32 available cores in a non-small calculation (80 x 64 x 320 points).  This is not a crime but is likely silly and therefore triggers an error.  Please use parallel={'augment_grids': True} or complain to the developers.  You can also disable this error by passing accept_partial_decomposition=True to the libvdwxc functional object, but be careful to use good domain decomposition.
GPAW CLEANUP (node 10): <class 'ValueError'> occurred.  Calling MPI_Abort!
rank=12 L00: Traceback (most recent call last):
rank=12 L01:   File "./job.py", line 20, in <module>
rank=12 L02:     relax = LBFGS(atoms=atoms, logfile='final_opt.log', trajectory='final_opt.traj')
rank=12 L03:   File "/uls/7/gpaw-20.1.0/lib/python3.8/site-packages/ase-3.20.1-py3.8.egg/ase/optimize/lbfgs.py", line 65, in __init__
rank=12 L04:     Optimizer.__init__(self, atoms, restart, logfile, trajectory, master,
rank=12 L05:   File "/uls/7/gpaw-20.1.0/lib/python3.8/site-packages/ase-3.20.1-py3.8.egg/ase/optimize/optimize.py", line 240, in __init__
rank=12 L06:     self.set_force_consistent()
rank=12 L07:   File "/uls/7/gpaw-20.1.0/lib/python3.8/site-packages/ase-3.20.1-py3.8.egg/ase/optimize/optimize.py", line 324, in set_force_consistent
rank=12 L08:     self.atoms.get_potential_energy(force_consistent=True)
rank=12 L09:   File "/uls/7/gpaw-20.1.0/lib/python3.8/site-packages/ase-3.20.1-py3.8.egg/ase/atoms.py", line 730, in get_potential_energy
rank=12 L10:     energy = self._calc.get_potential_energy(
rank=12 L11:   File "/uls/7/gpaw-20.1.0/lib/python3.8/site-packages/ase-3.20.1-py3.8.egg/ase/calculators/calculator.py", line 682, in get_potential_energy
rank=12 L12:     energy = self.get_property('energy', atoms)
rank=12 L13:   File "/uls/7/gpaw-20.1.0/lib/python3.8/site-packages/ase-3.20.1-py3.8.egg/ase/calculators/calculator.py", line 738, in get_property
rank=12 L14:     self.calculate(atoms, [name], system_changes)
rank=12 L15:   File "/uls/7/gpaw-20.1.0/lib/python3.8/site-packages/gpaw-20.1.0-py3.8-linux-x86_64.egg/gpaw/calculator.py", line 288, in calculate
rank=12 L16:     self.initialize(atoms)
rank=12 L17:   File "/uls/7/gpaw-20.1.0/lib/python3.8/site-packages/gpaw-20.1.0-py3.8-linux-x86_64.egg/gpaw/calculator.py", line 726, in initialize
rank=12 L18:     xc.initialize(self.density, self.hamiltonian, self.wfs,
rank=12 L19:   File "/uls/7/gpaw-20.1.0/lib/python3.8/site-packages/gpaw-20.1.0-py3.8-linux-x86_64.egg/gpaw/xc/libvdwxc.py", line 414, in initialize
rank=12 L20:     raise ValueError('You are using libvdwxc with only '
rank=12 L21: ValueError: You are using libvdwxc with only 4 out of 32 available cores in a non-small calculation (80 x 64 x 320 points).  This is not a crime but is likely silly and therefore triggers an error.  Please use parallel={'augment_grids': True} or complain to the developers.  You can also disable this error by passing accept_partial_decomposition=True to the libvdwxc functional object, but be careful to use good domain decomposition.
GPAW CLEANUP (node 12): <class 'ValueError'> occurred.  Calling MPI_Abort!
rank=16 L00: Traceback (most recent call last):
rank=16 L01:   File "./job.py", line 20, in <module>
rank=16 L02:     relax = LBFGS(atoms=atoms, logfile='final_opt.log', trajectory='final_opt.traj')
rank=16 L03:   File "/uls/7/gpaw-20.1.0/lib/python3.8/site-packages/ase-3.20.1-py3.8.egg/ase/optimize/lbfgs.py", line 65, in __init__
rank=16 L04:     Optimizer.__init__(self, atoms, restart, logfile, trajectory, master,
rank=16 L05:   File "/uls/7/gpaw-20.1.0/lib/python3.8/site-packages/ase-3.20.1-py3.8.egg/ase/optimize/optimize.py", line 240, in __init__
rank=16 L06:     self.set_force_consistent()
rank=16 L07:   File "/uls/7/gpaw-20.1.0/lib/python3.8/site-packages/ase-3.20.1-py3.8.egg/ase/optimize/optimize.py", line 324, in set_force_consistent
rank=16 L08:     self.atoms.get_potential_energy(force_consistent=True)
rank=16 L09:   File "/uls/7/gpaw-20.1.0/lib/python3.8/site-packages/ase-3.20.1-py3.8.egg/ase/atoms.py", line 730, in get_potential_energy
rank=16 L10:     energy = self._calc.get_potential_energy(
rank=16 L11:   File "/uls/7/gpaw-20.1.0/lib/python3.8/site-packages/ase-3.20.1-py3.8.egg/ase/calculators/calculator.py", line 682, in get_potential_energy
rank=16 L12:     energy = self.get_property('energy', atoms)
rank=16 L13:   File "/uls/7/gpaw-20.1.0/lib/python3.8/site-packages/ase-3.20.1-py3.8.egg/ase/calculators/calculator.py", line 738, in get_property
rank=16 L14:     self.calculate(atoms, [name], system_changes)
rank=16 L15:   File "/uls/7/gpaw-20.1.0/lib/python3.8/site-packages/gpaw-20.1.0-py3.8-linux-x86_64.egg/gpaw/calculator.py", line 288, in calculate
rank=16 L16:     self.initialize(atoms)
rank=16 L17:   File "/uls/7/gpaw-20.1.0/lib/python3.8/site-packages/gpaw-20.1.0-py3.8-linux-x86_64.egg/gpaw/calculator.py", line 726, in initialize
rank=16 L18:     xc.initialize(self.density, self.hamiltonian, self.wfs,
rank=16 L19:   File "/uls/7/gpaw-20.1.0/lib/python3.8/site-packages/gpaw-20.1.0-py3.8-linux-x86_64.egg/gpaw/xc/libvdwxc.py", line 414, in initialize
rank=16 L20:     raise ValueError('You are using libvdwxc with only '
rank=16 L21: ValueError: You are using libvdwxc with only 4 out of 32 available cores in a non-small calculation (80 x 64 x 320 points).  This is not a crime but is likely silly and therefore triggers an error.  Please use parallel={'augment_grids': True} or complain to the developers.  You can also disable this error by passing accept_partial_decomposition=True to the libvdwxc functional object, but be careful to use good domain decomposition.
GPAW CLEANUP (node 16): <class 'ValueError'> occurred.  Calling MPI_Abort!
rank=20 L00: Traceback (most recent call last):
rank=20 L01:   File "./job.py", line 20, in <module>
rank=20 L02:     relax = LBFGS(atoms=atoms, logfile='final_opt.log', trajectory='final_opt.traj')
rank=20 L03:   File "/uls/7/gpaw-20.1.0/lib/python3.8/site-packages/ase-3.20.1-py3.8.egg/ase/optimize/lbfgs.py", line 65, in __init__
rank=20 L04:     Optimizer.__init__(self, atoms, restart, logfile, trajectory, master,
rank=20 L05:   File "/uls/7/gpaw-20.1.0/lib/python3.8/site-packages/ase-3.20.1-py3.8.egg/ase/optimize/optimize.py", line 240, in __init__
rank=20 L06:     self.set_force_consistent()
rank=20 L07:   File "/uls/7/gpaw-20.1.0/lib/python3.8/site-packages/ase-3.20.1-py3.8.egg/ase/optimize/optimize.py", line 324, in set_force_consistent
rank=20 L08:     self.atoms.get_potential_energy(force_consistent=True)
rank=20 L09:   File "/uls/7/gpaw-20.1.0/lib/python3.8/site-packages/ase-3.20.1-py3.8.egg/ase/atoms.py", line 730, in get_potential_energy
rank=20 L10:     energy = self._calc.get_potential_energy(
rank=20 L11:   File "/uls/7/gpaw-20.1.0/lib/python3.8/site-packages/ase-3.20.1-py3.8.egg/ase/calculators/calculator.py", line 682, in get_potential_energy
rank=20 L12:     energy = self.get_property('energy', atoms)
rank=20 L13:   File "/uls/7/gpaw-20.1.0/lib/python3.8/site-packages/ase-3.20.1-py3.8.egg/ase/calculators/calculator.py", line 738, in get_property
rank=20 L14:     self.calculate(atoms, [name], system_changes)
rank=20 L15:   File "/uls/7/gpaw-20.1.0/lib/python3.8/site-packages/gpaw-20.1.0-py3.8-linux-x86_64.egg/gpaw/calculator.py", line 288, in calculate
rank=20 L16:     self.initialize(atoms)
rank=20 L17:   File "/uls/7/gpaw-20.1.0/lib/python3.8/site-packages/gpaw-20.1.0-py3.8-linux-x86_64.egg/gpaw/calculator.py", line 726, in initialize
rank=20 L18:     xc.initialize(self.density, self.hamiltonian, self.wfs,
rank=20 L19:   File "/uls/7/gpaw-20.1.0/lib/python3.8/site-packages/gpaw-20.1.0-py3.8-linux-x86_64.egg/gpaw/xc/libvdwxc.py", line 414, in initialize
rank=20 L20:     raise ValueError('You are using libvdwxc with only '
rank=20 L21: ValueError: You are using libvdwxc with only 4 out of 32 available cores in a non-small calculation (80 x 64 x 320 points).  This is not a crime but is likely silly and therefore triggers an error.  Please use parallel={'augment_grids': True} or complain to the developers.  You can also disable this error by passing accept_partial_decomposition=True to the libvdwxc functional object, but be careful to use good domain decomposition.
GPAW CLEANUP (node 20): <class 'ValueError'> occurred.  Calling MPI_Abort!
rank=22 L00: Traceback (most recent call last):
rank=22 L01:   File "./job.py", line 20, in <module>
rank=22 L02:     relax = LBFGS(atoms=atoms, logfile='final_opt.log', trajectory='final_opt.traj')
rank=22 L03:   File "/uls/7/gpaw-20.1.0/lib/python3.8/site-packages/ase-3.20.1-py3.8.egg/ase/optimize/lbfgs.py", line 65, in __init__
rank=22 L04:     Optimizer.__init__(self, atoms, restart, logfile, trajectory, master,
rank=22 L05:   File "/uls/7/gpaw-20.1.0/lib/python3.8/site-packages/ase-3.20.1-py3.8.egg/ase/optimize/optimize.py", line 240, in __init__
rank=22 L06:     self.set_force_consistent()
rank=22 L07:   File "/uls/7/gpaw-20.1.0/lib/python3.8/site-packages/ase-3.20.1-py3.8.egg/ase/optimize/optimize.py", line 324, in set_force_consistent
rank=22 L08:     self.atoms.get_potential_energy(force_consistent=True)
rank=22 L09:   File "/uls/7/gpaw-20.1.0/lib/python3.8/site-packages/ase-3.20.1-py3.8.egg/ase/atoms.py", line 730, in get_potential_energy
rank=22 L10:     energy = self._calc.get_potential_energy(
rank=22 L11:   File "/uls/7/gpaw-20.1.0/lib/python3.8/site-packages/ase-3.20.1-py3.8.egg/ase/calculators/calculator.py", line 682, in get_potential_energy
rank=22 L12:     energy = self.get_property('energy', atoms)
rank=22 L13:   File "/uls/7/gpaw-20.1.0/lib/python3.8/site-packages/ase-3.20.1-py3.8.egg/ase/calculators/calculator.py", line 738, in get_property
rank=22 L14:     self.calculate(atoms, [name], system_changes)
rank=22 L15:   File "/uls/7/gpaw-20.1.0/lib/python3.8/site-packages/gpaw-20.1.0-py3.8-linux-x86_64.egg/gpaw/calculator.py", line 288, in calculate
rank=22 L16:     self.initialize(atoms)
rank=22 L17:   File "/uls/7/gpaw-20.1.0/lib/python3.8/site-packages/gpaw-20.1.0-py3.8-linux-x86_64.egg/gpaw/calculator.py", line 726, in initialize
rank=22 L18:     xc.initialize(self.density, self.hamiltonian, self.wfs,
rank=22 L19:   File "/uls/7/gpaw-20.1.0/lib/python3.8/site-packages/gpaw-20.1.0-py3.8-linux-x86_64.egg/gpaw/xc/libvdwxc.py", line 414, in initialize
rank=22 L20:     raise ValueError('You are using libvdwxc with only '
rank=22 L21: ValueError: You are using libvdwxc with only 4 out of 32 available cores in a non-small calculation (80 x 64 x 320 points).  This is not a crime but is likely silly and therefore triggers an error.  Please use parallel={'augment_grids': True} or complain to the developers.  You can also disable this error by passing accept_partial_decomposition=True to the libvdwxc functional object, but be careful to use good domain decomposition.
GPAW CLEANUP (node 22): <class 'ValueError'> occurred.  Calling MPI_Abort!
rank=28 L00: Traceback (most recent call last):
rank=28 L01:   File "./job.py", line 20, in <module>
rank=28 L02:     relax = LBFGS(atoms=atoms, logfile='final_opt.log', trajectory='final_opt.traj')
rank=28 L03:   File "/uls/7/gpaw-20.1.0/lib/python3.8/site-packages/ase-3.20.1-py3.8.egg/ase/optimize/lbfgs.py", line 65, in __init__
rank=28 L04:     Optimizer.__init__(self, atoms, restart, logfile, trajectory, master,
rank=28 L05:   File "/uls/7/gpaw-20.1.0/lib/python3.8/site-packages/ase-3.20.1-py3.8.egg/ase/optimize/optimize.py", line 240, in __init__
rank=28 L06:     self.set_force_consistent()
rank=28 L07:   File "/uls/7/gpaw-20.1.0/lib/python3.8/site-packages/ase-3.20.1-py3.8.egg/ase/optimize/optimize.py", line 324, in set_force_consistent
rank=28 L08:     self.atoms.get_potential_energy(force_consistent=True)
rank=28 L09:   File "/uls/7/gpaw-20.1.0/lib/python3.8/site-packages/ase-3.20.1-py3.8.egg/ase/atoms.py", line 730, in get_potential_energy
rank=28 L10:     energy = self._calc.get_potential_energy(
rank=28 L11:   File "/uls/7/gpaw-20.1.0/lib/python3.8/site-packages/ase-3.20.1-py3.8.egg/ase/calculators/calculator.py", line 682, in get_potential_energy
rank=28 L12:     energy = self.get_property('energy', atoms)
rank=28 L13:   File "/uls/7/gpaw-20.1.0/lib/python3.8/site-packages/ase-3.20.1-py3.8.egg/ase/calculators/calculator.py", line 738, in get_property
rank=28 L14:     self.calculate(atoms, [name], system_changes)
rank=28 L15:   File "/uls/7/gpaw-20.1.0/lib/python3.8/site-packages/gpaw-20.1.0-py3.8-linux-x86_64.egg/gpaw/calculator.py", line 288, in calculate
rank=28 L16:     self.initialize(atoms)
rank=28 L17:   File "/uls/7/gpaw-20.1.0/lib/python3.8/site-packages/gpaw-20.1.0-py3.8-linux-x86_64.egg/gpaw/calculator.py", line 726, in initialize
rank=28 L18:     xc.initialize(self.density, self.hamiltonian, self.wfs,
rank=28 L19:   File "/uls/7/gpaw-20.1.0/lib/python3.8/site-packages/gpaw-20.1.0-py3.8-linux-x86_64.egg/gpaw/xc/libvdwxc.py", line 414, in initialize
rank=28 L20:     raise ValueError('You are using libvdwxc with only '
rank=28 L21: ValueError: You are using libvdwxc with only 4 out of 32 available cores in a non-small calculation (80 x 64 x 320 points).  This is not a crime but is likely silly and therefore triggers an error.  Please use parallel={'augment_grids': True} or complain to the developers.  You can also disable this error by passing accept_partial_decomposition=True to the libvdwxc functional object, but be careful to use good domain decomposition.
GPAW CLEANUP (node 28): <class 'ValueError'> occurred.  Calling MPI_Abort!
rank=29 L00: Traceback (most recent call last):
rank=29 L01:   File "./job.py", line 20, in <module>
rank=29 L02:     relax = LBFGS(atoms=atoms, logfile='final_opt.log', trajectory='final_opt.traj')
rank=29 L03:   File "/uls/7/gpaw-20.1.0/lib/python3.8/site-packages/ase-3.20.1-py3.8.egg/ase/optimize/lbfgs.py", line 65, in __init__
rank=29 L04:     Optimizer.__init__(self, atoms, restart, logfile, trajectory, master,
rank=29 L05:   File "/uls/7/gpaw-20.1.0/lib/python3.8/site-packages/ase-3.20.1-py3.8.egg/ase/optimize/optimize.py", line 240, in __init__
rank=29 L06:     self.set_force_consistent()
rank=29 L07:   File "/uls/7/gpaw-20.1.0/lib/python3.8/site-packages/ase-3.20.1-py3.8.egg/ase/optimize/optimize.py", line 324, in set_force_consistent
rank=29 L08:     self.atoms.get_potential_energy(force_consistent=True)
rank=29 L09:   File "/uls/7/gpaw-20.1.0/lib/python3.8/site-packages/ase-3.20.1-py3.8.egg/ase/atoms.py", line 730, in get_potential_energy
rank=29 L10:     energy = self._calc.get_potential_energy(
rank=29 L11:   File "/uls/7/gpaw-20.1.0/lib/python3.8/site-packages/ase-3.20.1-py3.8.egg/ase/calculators/calculator.py", line 682, in get_potential_energy
rank=29 L12:     energy = self.get_property('energy', atoms)
rank=29 L13:   File "/uls/7/gpaw-20.1.0/lib/python3.8/site-packages/ase-3.20.1-py3.8.egg/ase/calculators/calculator.py", line 738, in get_property
rank=29 L14:     self.calculate(atoms, [name], system_changes)
rank=29 L15:   File "/uls/7/gpaw-20.1.0/lib/python3.8/site-packages/gpaw-20.1.0-py3.8-linux-x86_64.egg/gpaw/calculator.py", line 288, in calculate
rank=29 L16:     self.initialize(atoms)
rank=29 L17:   File "/uls/7/gpaw-20.1.0/lib/python3.8/site-packages/gpaw-20.1.0-py3.8-linux-x86_64.egg/gpaw/calculator.py", line 726, in initialize
rank=29 L18:     xc.initialize(self.density, self.hamiltonian, self.wfs,
rank=29 L19:   File "/uls/7/gpaw-20.1.0/lib/python3.8/site-packages/gpaw-20.1.0-py3.8-linux-x86_64.egg/gpaw/xc/libvdwxc.py", line 414, in initialize
rank=29 L20:     raise ValueError('You are using libvdwxc with only '
rank=29 L21: ValueError: You are using libvdwxc with only 4 out of 32 available cores in a non-small calculation (80 x 64 x 320 points).  This is not a crime but is likely silly and therefore triggers an error.  Please use parallel={'augment_grids': True} or complain to the developers.  You can also disable this error by passing accept_partial_decomposition=True to the libvdwxc functional object, but be careful to use good domain decomposition.
GPAW CLEANUP (node 29): <class 'ValueError'> occurred.  Calling MPI_Abort!
rank=30 L00: Traceback (most recent call last):
rank=30 L01:   File "./job.py", line 20, in <module>
rank=30 L02:     relax = LBFGS(atoms=atoms, logfile='final_opt.log', trajectory='final_opt.traj')
rank=30 L03:   File "/uls/7/gpaw-20.1.0/lib/python3.8/site-packages/ase-3.20.1-py3.8.egg/ase/optimize/lbfgs.py", line 65, in __init__
rank=30 L04:     Optimizer.__init__(self, atoms, restart, logfile, trajectory, master,
rank=30 L05:   File "/uls/7/gpaw-20.1.0/lib/python3.8/site-packages/ase-3.20.1-py3.8.egg/ase/optimize/optimize.py", line 240, in __init__
rank=30 L06:     self.set_force_consistent()
rank=30 L07:   File "/uls/7/gpaw-20.1.0/lib/python3.8/site-packages/ase-3.20.1-py3.8.egg/ase/optimize/optimize.py", line 324, in set_force_consistent
rank=30 L08:     self.atoms.get_potential_energy(force_consistent=True)
rank=30 L09:   File "/uls/7/gpaw-20.1.0/lib/python3.8/site-packages/ase-3.20.1-py3.8.egg/ase/atoms.py", line 730, in get_potential_energy
rank=30 L10:     energy = self._calc.get_potential_energy(
rank=30 L11:   File "/uls/7/gpaw-20.1.0/lib/python3.8/site-packages/ase-3.20.1-py3.8.egg/ase/calculators/calculator.py", line 682, in get_potential_energy
rank=30 L12:     energy = self.get_property('energy', atoms)
rank=30 L13:   File "/uls/7/gpaw-20.1.0/lib/python3.8/site-packages/ase-3.20.1-py3.8.egg/ase/calculators/calculator.py", line 738, in get_property
rank=30 L14:     self.calculate(atoms, [name], system_changes)
rank=30 L15:   File "/uls/7/gpaw-20.1.0/lib/python3.8/site-packages/gpaw-20.1.0-py3.8-linux-x86_64.egg/gpaw/calculator.py", line 288, in calculate
rank=30 L16:     self.initialize(atoms)
rank=30 L17:   File "/uls/7/gpaw-20.1.0/lib/python3.8/site-packages/gpaw-20.1.0-py3.8-linux-x86_64.egg/gpaw/calculator.py", line 726, in initialize
rank=30 L18:     xc.initialize(self.density, self.hamiltonian, self.wfs,
rank=30 L19:   File "/uls/7/gpaw-20.1.0/lib/python3.8/site-packages/gpaw-20.1.0-py3.8-linux-x86_64.egg/gpaw/xc/libvdwxc.py", line 414, in initialize
rank=30 L20:     raise ValueError('You are using libvdwxc with only '
rank=30 L21: ValueError: You are using libvdwxc with only 4 out of 32 available cores in a non-small calculation (80 x 64 x 320 points).  This is not a crime but is likely silly and therefore triggers an error.  Please use parallel={'augment_grids': True} or complain to the developers.  You can also disable this error by passing accept_partial_decomposition=True to the libvdwxc functional object, but be careful to use good domain decomposition.
GPAW CLEANUP (node 30): <class 'ValueError'> occurred.  Calling MPI_Abort!
rank=24 L00: Traceback (most recent call last):
rank=24 L01:   File "./job.py", line 20, in <module>
rank=24 L02:     relax = LBFGS(atoms=atoms, logfile='final_opt.log', trajectory='final_opt.traj')
rank=24 L03:   File "/uls/7/gpaw-20.1.0/lib/python3.8/site-packages/ase-3.20.1-py3.8.egg/ase/optimize/lbfgs.py", line 65, in __init__
rank=24 L04:     Optimizer.__init__(self, atoms, restart, logfile, trajectory, master,
rank=24 L05:   File "/uls/7/gpaw-20.1.0/lib/python3.8/site-packages/ase-3.20.1-py3.8.egg/ase/optimize/optimize.py", line 240, in __init__
rank=24 L06:     self.set_force_consistent()
rank=24 L07:   File "/uls/7/gpaw-20.1.0/lib/python3.8/site-packages/ase-3.20.1-py3.8.egg/ase/optimize/optimize.py", line 324, in set_force_consistent
rank=24 L08:     self.atoms.get_potential_energy(force_consistent=True)
rank=24 L09:   File "/uls/7/gpaw-20.1.0/lib/python3.8/site-packages/ase-3.20.1-py3.8.egg/ase/atoms.py", line 730, in get_potential_energy
rank=24 L10:     energy = self._calc.get_potential_energy(
rank=24 L11:   File "/uls/7/gpaw-20.1.0/lib/python3.8/site-packages/ase-3.20.1-py3.8.egg/ase/calculators/calculator.py", line 682, in get_potential_energy
rank=24 L12:     energy = self.get_property('energy', atoms)
rank=24 L13:   File "/uls/7/gpaw-20.1.0/lib/python3.8/site-packages/ase-3.20.1-py3.8.egg/ase/calculators/calculator.py", line 738, in get_property
rank=24 L14:     self.calculate(atoms, [name], system_changes)
rank=24 L15:   File "/uls/7/gpaw-20.1.0/lib/python3.8/site-packages/gpaw-20.1.0-py3.8-linux-x86_64.egg/gpaw/calculator.py", line 288, in calculate
rank=24 L16:     self.initialize(atoms)
rank=24 L17:   File "/uls/7/gpaw-20.1.0/lib/python3.8/site-packages/gpaw-20.1.0-py3.8-linux-x86_64.egg/gpaw/calculator.py", line 726, in initialize
rank=24 L18:     xc.initialize(self.density, self.hamiltonian, self.wfs,
rank=24 L19:   File "/uls/7/gpaw-20.1.0/lib/python3.8/site-packages/gpaw-20.1.0-py3.8-linux-x86_64.egg/gpaw/xc/libvdwxc.py", line 414, in initialize
rank=24 L20:     raise ValueError('You are using libvdwxc with only '
rank=24 L21: ValueError: You are using libvdwxc with only 4 out of 32 available cores in a non-small calculation (80 x 64 x 320 points).  This is not a crime but is likely silly and therefore triggers an error.  Please use parallel={'augment_grids': True} or complain to the developers.  You can also disable this error by passing accept_partial_decomposition=True to the libvdwxc functional object, but be careful to use good domain decomposition.
GPAW CLEANUP (node 24): <class 'ValueError'> occurred.  Calling MPI_Abort!
rank=27 L00: Traceback (most recent call last):
rank=27 L01:   File "./job.py", line 20, in <module>
rank=27 L02:     relax = LBFGS(atoms=atoms, logfile='final_opt.log', trajectory='final_opt.traj')
rank=27 L03:   File "/uls/7/gpaw-20.1.0/lib/python3.8/site-packages/ase-3.20.1-py3.8.egg/ase/optimize/lbfgs.py", line 65, in __init__
rank=27 L04:     Optimizer.__init__(self, atoms, restart, logfile, trajectory, master,
rank=27 L05:   File "/uls/7/gpaw-20.1.0/lib/python3.8/site-packages/ase-3.20.1-py3.8.egg/ase/optimize/optimize.py", line 240, in __init__
rank=27 L06:     self.set_force_consistent()
rank=27 L07:   File "/uls/7/gpaw-20.1.0/lib/python3.8/site-packages/ase-3.20.1-py3.8.egg/ase/optimize/optimize.py", line 324, in set_force_consistent
rank=27 L08:     self.atoms.get_potential_energy(force_consistent=True)
rank=27 L09:   File "/uls/7/gpaw-20.1.0/lib/python3.8/site-packages/ase-3.20.1-py3.8.egg/ase/atoms.py", line 730, in get_potential_energy
rank=27 L10:     energy = self._calc.get_potential_energy(
rank=27 L11:   File "/uls/7/gpaw-20.1.0/lib/python3.8/site-packages/ase-3.20.1-py3.8.egg/ase/calculators/calculator.py", line 682, in get_potential_energy
rank=27 L12:     energy = self.get_property('energy', atoms)
rank=27 L13:   File "/uls/7/gpaw-20.1.0/lib/python3.8/site-packages/ase-3.20.1-py3.8.egg/ase/calculators/calculator.py", line 738, in get_property
rank=27 L14:     self.calculate(atoms, [name], system_changes)
rank=27 L15:   File "/uls/7/gpaw-20.1.0/lib/python3.8/site-packages/gpaw-20.1.0-py3.8-linux-x86_64.egg/gpaw/calculator.py", line 288, in calculate
rank=27 L16:     self.initialize(atoms)
rank=27 L17:   File "/uls/7/gpaw-20.1.0/lib/python3.8/site-packages/gpaw-20.1.0-py3.8-linux-x86_64.egg/gpaw/calculator.py", line 726, in initialize
rank=27 L18:     xc.initialize(self.density, self.hamiltonian, self.wfs,
rank=27 L19:   File "/uls/7/gpaw-20.1.0/lib/python3.8/site-packages/gpaw-20.1.0-py3.8-linux-x86_64.egg/gpaw/xc/libvdwxc.py", line 414, in initialize
rank=27 L20:     raise ValueError('You are using libvdwxc with only '
rank=27 L21: ValueError: You are using libvdwxc with only 4 out of 32 available cores in a non-small calculation (80 x 64 x 320 points).  This is not a crime but is likely silly and therefore triggers an error.  Please use parallel={'augment_grids': True} or complain to the developers.  You can also disable this error by passing accept_partial_decomposition=True to the libvdwxc functional object, but be careful to use good domain decomposition.
GPAW CLEANUP (node 27): <class 'ValueError'> occurred.  Calling MPI_Abort!
rank=18 L00: Traceback (most recent call last):
rank=18 L01:   File "./job.py", line 20, in <module>
rank=18 L02:     relax = LBFGS(atoms=atoms, logfile='final_opt.log', trajectory='final_opt.traj')
rank=18 L03:   File "/uls/7/gpaw-20.1.0/lib/python3.8/site-packages/ase-3.20.1-py3.8.egg/ase/optimize/lbfgs.py", line 65, in __init__
rank=18 L04:     Optimizer.__init__(self, atoms, restart, logfile, trajectory, master,
rank=18 L05:   File "/uls/7/gpaw-20.1.0/lib/python3.8/site-packages/ase-3.20.1-py3.8.egg/ase/optimize/optimize.py", line 240, in __init__
rank=18 L06:     self.set_force_consistent()
rank=18 L07:   File "/uls/7/gpaw-20.1.0/lib/python3.8/site-packages/ase-3.20.1-py3.8.egg/ase/optimize/optimize.py", line 324, in set_force_consistent
rank=18 L08:     self.atoms.get_potential_energy(force_consistent=True)
rank=18 L09:   File "/uls/7/gpaw-20.1.0/lib/python3.8/site-packages/ase-3.20.1-py3.8.egg/ase/atoms.py", line 730, in get_potential_energy
rank=18 L10:     energy = self._calc.get_potential_energy(
rank=18 L11:   File "/uls/7/gpaw-20.1.0/lib/python3.8/site-packages/ase-3.20.1-py3.8.egg/ase/calculators/calculator.py", line 682, in get_potential_energy
rank=18 L12:     energy = self.get_property('energy', atoms)
rank=18 L13:   File "/uls/7/gpaw-20.1.0/lib/python3.8/site-packages/ase-3.20.1-py3.8.egg/ase/calculators/calculator.py", line 738, in get_property
rank=18 L14:     self.calculate(atoms, [name], system_changes)
rank=18 L15:   File "/uls/7/gpaw-20.1.0/lib/python3.8/site-packages/gpaw-20.1.0-py3.8-linux-x86_64.egg/gpaw/calculator.py", line 288, in calculate
rank=18 L16:     self.initialize(atoms)
rank=18 L17:   File "/uls/7/gpaw-20.1.0/lib/python3.8/site-packages/gpaw-20.1.0-py3.8-linux-x86_64.egg/gpaw/calculator.py", line 726, in initialize
rank=18 L18:     xc.initialize(self.density, self.hamiltonian, self.wfs,
rank=18 L19:   File "/uls/7/gpaw-20.1.0/lib/python3.8/site-packages/gpaw-20.1.0-py3.8-linux-x86_64.egg/gpaw/xc/libvdwxc.py", line 414, in initialize
rank=18 L20:     raise ValueError('You are using libvdwxc with only '
rank=18 L21: ValueError: You are using libvdwxc with only 4 out of 32 available cores in a non-small calculation (80 x 64 x 320 points).  This is not a crime but is likely silly and therefore triggers an error.  Please use parallel={'augment_grids': True} or complain to the developers.  You can also disable this error by passing accept_partial_decomposition=True to the libvdwxc functional object, but be careful to use good domain decomposition.
GPAW CLEANUP (node 18): <class 'ValueError'> occurred.  Calling MPI_Abort!
rank=01 L00: Traceback (most recent call last):
rank=01 L01:   File "./job.py", line 20, in <module>
rank=01 L02:     relax = LBFGS(atoms=atoms, logfile='final_opt.log', trajectory='final_opt.traj')
rank=01 L03:   File "/uls/7/gpaw-20.1.0/lib/python3.8/site-packages/ase-3.20.1-py3.8.egg/ase/optimize/lbfgs.py", line 65, in __init__
rank=01 L04:     Optimizer.__init__(self, atoms, restart, logfile, trajectory, master,
rank=01 L05:   File "/uls/7/gpaw-20.1.0/lib/python3.8/site-packages/ase-3.20.1-py3.8.egg/ase/optimize/optimize.py", line 240, in __init__
rank=01 L06:     self.set_force_consistent()
rank=01 L07:   File "/uls/7/gpaw-20.1.0/lib/python3.8/site-packages/ase-3.20.1-py3.8.egg/ase/optimize/optimize.py", line 324, in set_force_consistent
rank=01 L08:     self.atoms.get_potential_energy(force_consistent=True)
rank=01 L09:   File "/uls/7/gpaw-20.1.0/lib/python3.8/site-packages/ase-3.20.1-py3.8.egg/ase/atoms.py", line 730, in get_potential_energy
rank=01 L10:     energy = self._calc.get_potential_energy(
rank=01 L11:   File "/uls/7/gpaw-20.1.0/lib/python3.8/site-packages/ase-3.20.1-py3.8.egg/ase/calculators/calculator.py", line 682, in get_potential_energy
rank=01 L12:     energy = self.get_property('energy', atoms)
rank=01 L13:   File "/uls/7/gpaw-20.1.0/lib/python3.8/site-packages/ase-3.20.1-py3.8.egg/ase/calculators/calculator.py", line 738, in get_property
rank=01 L14:     self.calculate(atoms, [name], system_changes)
rank=01 L15:   File "/uls/7/gpaw-20.1.0/lib/python3.8/site-packages/gpaw-20.1.0-py3.8-linux-x86_64.egg/gpaw/calculator.py", line 288, in calculate
rank=01 L16:     self.initialize(atoms)
rank=01 L17:   File "/uls/7/gpaw-20.1.0/lib/python3.8/site-packages/gpaw-20.1.0-py3.8-linux-x86_64.egg/gpaw/calculator.py", line 726, in initialize
rank=01 L18:     xc.initialize(self.density, self.hamiltonian, self.wfs,
rank=01 L19:   File "/uls/7/gpaw-20.1.0/lib/python3.8/site-packages/gpaw-20.1.0-py3.8-linux-x86_64.egg/gpaw/xc/libvdwxc.py", line 414, in initialize
rank=01 L20:     raise ValueError('You are using libvdwxc with only '
rank=01 L21: ValueError: You are using libvdwxc with only 4 out of 32 available cores in a non-small calculation (80 x 64 x 320 points).  This is not a crime but is likely silly and therefore triggers an error.  Please use parallel={'augment_grids': True} or complain to the developers.  You can also disable this error by passing accept_partial_decomposition=True to the libvdwxc functional object, but be careful to use good domain decomposition.
GPAW CLEANUP (node 1): <class 'ValueError'> occurred.  Calling MPI_Abort!
rank=14 L00: Traceback (most recent call last):
rank=14 L01:   File "./job.py", line 20, in <module>
rank=14 L02:     relax = LBFGS(atoms=atoms, logfile='final_opt.log', trajectory='final_opt.traj')
rank=14 L03:   File "/uls/7/gpaw-20.1.0/lib/python3.8/site-packages/ase-3.20.1-py3.8.egg/ase/optimize/lbfgs.py", line 65, in __init__
rank=14 L04:     Optimizer.__init__(self, atoms, restart, logfile, trajectory, master,
rank=14 L05:   File "/uls/7/gpaw-20.1.0/lib/python3.8/site-packages/ase-3.20.1-py3.8.egg/ase/optimize/optimize.py", line 240, in __init__
rank=14 L06:     self.set_force_consistent()
rank=14 L07:   File "/uls/7/gpaw-20.1.0/lib/python3.8/site-packages/ase-3.20.1-py3.8.egg/ase/optimize/optimize.py", line 324, in set_force_consistent
rank=14 L08:     self.atoms.get_potential_energy(force_consistent=True)
rank=14 L09:   File "/uls/7/gpaw-20.1.0/lib/python3.8/site-packages/ase-3.20.1-py3.8.egg/ase/atoms.py", line 730, in get_potential_energy
rank=14 L10:     energy = self._calc.get_potential_energy(
rank=14 L11:   File "/uls/7/gpaw-20.1.0/lib/python3.8/site-packages/ase-3.20.1-py3.8.egg/ase/calculators/calculator.py", line 682, in get_potential_energy
rank=14 L12:     energy = self.get_property('energy', atoms)
rank=14 L13:   File "/uls/7/gpaw-20.1.0/lib/python3.8/site-packages/ase-3.20.1-py3.8.egg/ase/calculators/calculator.py", line 738, in get_property
rank=14 L14:     self.calculate(atoms, [name], system_changes)
rank=14 L15:   File "/uls/7/gpaw-20.1.0/lib/python3.8/site-packages/gpaw-20.1.0-py3.8-linux-x86_64.egg/gpaw/calculator.py", line 288, in calculate
rank=14 L16:     self.initialize(atoms)
rank=14 L17:   File "/uls/7/gpaw-20.1.0/lib/python3.8/site-packages/gpaw-20.1.0-py3.8-linux-x86_64.egg/gpaw/calculator.py", line 726, in initialize
rank=14 L18:     xc.initialize(self.density, self.hamiltonian, self.wfs,
rank=14 L19:   File "/uls/7/gpaw-20.1.0/lib/python3.8/site-packages/gpaw-20.1.0-py3.8-linux-x86_64.egg/gpaw/xc/libvdwxc.py", line 414, in initialize
rank=14 L20:     raise ValueError('You are using libvdwxc with only '
rank=14 L21: ValueError: You are using libvdwxc with only 4 out of 32 available cores in a non-small calculation (80 x 64 x 320 points).  This is not a crime but is likely silly and therefore triggers an error.  Please use parallel={'augment_grids': True} or complain to the developers.  You can also disable this error by passing accept_partial_decomposition=True to the libvdwxc functional object, but be careful to use good domain decomposition.
GPAW CLEANUP (node 14): <class 'ValueError'> occurred.  Calling MPI_Abort!
rank=25 L00: Traceback (most recent call last):
rank=25 L01:   File "./job.py", line 20, in <module>
rank=25 L02:     relax = LBFGS(atoms=atoms, logfile='final_opt.log', trajectory='final_opt.traj')
rank=25 L03:   File "/uls/7/gpaw-20.1.0/lib/python3.8/site-packages/ase-3.20.1-py3.8.egg/ase/optimize/lbfgs.py", line 65, in __init__
rank=25 L04:     Optimizer.__init__(self, atoms, restart, logfile, trajectory, master,
rank=25 L05:   File "/uls/7/gpaw-20.1.0/lib/python3.8/site-packages/ase-3.20.1-py3.8.egg/ase/optimize/optimize.py", line 240, in __init__
rank=25 L06:     self.set_force_consistent()
rank=25 L07:   File "/uls/7/gpaw-20.1.0/lib/python3.8/site-packages/ase-3.20.1-py3.8.egg/ase/optimize/optimize.py", line 324, in set_force_consistent
rank=25 L08:     self.atoms.get_potential_energy(force_consistent=True)
rank=25 L09:   File "/uls/7/gpaw-20.1.0/lib/python3.8/site-packages/ase-3.20.1-py3.8.egg/ase/atoms.py", line 730, in get_potential_energy
rank=25 L10:     energy = self._calc.get_potential_energy(
rank=25 L11:   File "/uls/7/gpaw-20.1.0/lib/python3.8/site-packages/ase-3.20.1-py3.8.egg/ase/calculators/calculator.py", line 682, in get_potential_energy
rank=25 L12:     energy = self.get_property('energy', atoms)
rank=25 L13:   File "/uls/7/gpaw-20.1.0/lib/python3.8/site-packages/ase-3.20.1-py3.8.egg/ase/calculators/calculator.py", line 738, in get_property
rank=25 L14:     self.calculate(atoms, [name], system_changes)
rank=25 L15:   File "/uls/7/gpaw-20.1.0/lib/python3.8/site-packages/gpaw-20.1.0-py3.8-linux-x86_64.egg/gpaw/calculator.py", line 288, in calculate
rank=25 L16:     self.initialize(atoms)
rank=25 L17:   File "/uls/7/gpaw-20.1.0/lib/python3.8/site-packages/gpaw-20.1.0-py3.8-linux-x86_64.egg/gpaw/calculator.py", line 726, in initialize
rank=25 L18:     xc.initialize(self.density, self.hamiltonian, self.wfs,
rank=25 L19:   File "/uls/7/gpaw-20.1.0/lib/python3.8/site-packages/gpaw-20.1.0-py3.8-linux-x86_64.egg/gpaw/xc/libvdwxc.py", line 414, in initialize
rank=25 L20:     raise ValueError('You are using libvdwxc with only '
rank=25 L21: ValueError: You are using libvdwxc with only 4 out of 32 available cores in a non-small calculation (80 x 64 x 320 points).  This is not a crime but is likely silly and therefore triggers an error.  Please use parallel={'augment_grids': True} or complain to the developers.  You can also disable this error by passing accept_partial_decomposition=True to the libvdwxc functional object, but be careful to use good domain decomposition.
GPAW CLEANUP (node 25): <class 'ValueError'> occurred.  Calling MPI_Abort!
rank=21 L00: Traceback (most recent call last):
rank=21 L01:   File "./job.py", line 20, in <module>
rank=21 L02:     relax = LBFGS(atoms=atoms, logfile='final_opt.log', trajectory='final_opt.traj')
rank=21 L03:   File "/uls/7/gpaw-20.1.0/lib/python3.8/site-packages/ase-3.20.1-py3.8.egg/ase/optimize/lbfgs.py", line 65, in __init__
rank=21 L04:     Optimizer.__init__(self, atoms, restart, logfile, trajectory, master,
rank=21 L05:   File "/uls/7/gpaw-20.1.0/lib/python3.8/site-packages/ase-3.20.1-py3.8.egg/ase/optimize/optimize.py", line 240, in __init__
rank=21 L06:     self.set_force_consistent()
rank=21 L07:   File "/uls/7/gpaw-20.1.0/lib/python3.8/site-packages/ase-3.20.1-py3.8.egg/ase/optimize/optimize.py", line 324, in set_force_consistent
rank=21 L08:     self.atoms.get_potential_energy(force_consistent=True)
rank=21 L09:   File "/uls/7/gpaw-20.1.0/lib/python3.8/site-packages/ase-3.20.1-py3.8.egg/ase/atoms.py", line 730, in get_potential_energy
rank=21 L10:     energy = self._calc.get_potential_energy(
rank=21 L11:   File "/uls/7/gpaw-20.1.0/lib/python3.8/site-packages/ase-3.20.1-py3.8.egg/ase/calculators/calculator.py", line 682, in get_potential_energy
rank=21 L12:     energy = self.get_property('energy', atoms)
rank=21 L13:   File "/uls/7/gpaw-20.1.0/lib/python3.8/site-packages/ase-3.20.1-py3.8.egg/ase/calculators/calculator.py", line 738, in get_property
rank=21 L14:     self.calculate(atoms, [name], system_changes)
rank=21 L15:   File "/uls/7/gpaw-20.1.0/lib/python3.8/site-packages/gpaw-20.1.0-py3.8-linux-x86_64.egg/gpaw/calculator.py", line 288, in calculate
rank=21 L16:     self.initialize(atoms)
rank=21 L17:   File "/uls/7/gpaw-20.1.0/lib/python3.8/site-packages/gpaw-20.1.0-py3.8-linux-x86_64.egg/gpaw/calculator.py", line 726, in initialize
rank=21 L18:     xc.initialize(self.density, self.hamiltonian, self.wfs,
rank=21 L19:   File "/uls/7/gpaw-20.1.0/lib/python3.8/site-packages/gpaw-20.1.0-py3.8-linux-x86_64.egg/gpaw/xc/libvdwxc.py", line 414, in initialize
rank=21 L20:     raise ValueError('You are using libvdwxc with only '
rank=21 L21: ValueError: You are using libvdwxc with only 4 out of 32 available cores in a non-small calculation (80 x 64 x 320 points).  This is not a crime but is likely silly and therefore triggers an error.  Please use parallel={'augment_grids': True} or complain to the developers.  You can also disable this error by passing accept_partial_decomposition=True to the libvdwxc functional object, but be careful to use good domain decomposition.
GPAW CLEANUP (node 21): <class 'ValueError'> occurred.  Calling MPI_Abort!
rank=19 L00: Traceback (most recent call last):
rank=19 L01:   File "./job.py", line 20, in <module>
rank=19 L02:     relax = LBFGS(atoms=atoms, logfile='final_opt.log', trajectory='final_opt.traj')
rank=19 L03:   File "/uls/7/gpaw-20.1.0/lib/python3.8/site-packages/ase-3.20.1-py3.8.egg/ase/optimize/lbfgs.py", line 65, in __init__
rank=19 L04:     Optimizer.__init__(self, atoms, restart, logfile, trajectory, master,
rank=19 L05:   File "/uls/7/gpaw-20.1.0/lib/python3.8/site-packages/ase-3.20.1-py3.8.egg/ase/optimize/optimize.py", line 240, in __init__
rank=19 L06:     self.set_force_consistent()
rank=19 L07:   File "/uls/7/gpaw-20.1.0/lib/python3.8/site-packages/ase-3.20.1-py3.8.egg/ase/optimize/optimize.py", line 324, in set_force_consistent
rank=19 L08:     self.atoms.get_potential_energy(force_consistent=True)
rank=19 L09:   File "/uls/7/gpaw-20.1.0/lib/python3.8/site-packages/ase-3.20.1-py3.8.egg/ase/atoms.py", line 730, in get_potential_energy
rank=19 L10:     energy = self._calc.get_potential_energy(
rank=19 L11:   File "/uls/7/gpaw-20.1.0/lib/python3.8/site-packages/ase-3.20.1-py3.8.egg/ase/calculators/calculator.py", line 682, in get_potential_energy
rank=19 L12:     energy = self.get_property('energy', atoms)
rank=19 L13:   File "/uls/7/gpaw-20.1.0/lib/python3.8/site-packages/ase-3.20.1-py3.8.egg/ase/calculators/calculator.py", line 738, in get_property
rank=19 L14:     self.calculate(atoms, [name], system_changes)
rank=19 L15:   File "/uls/7/gpaw-20.1.0/lib/python3.8/site-packages/gpaw-20.1.0-py3.8-linux-x86_64.egg/gpaw/calculator.py", line 288, in calculate
rank=19 L16:     self.initialize(atoms)
rank=19 L17:   File "/uls/7/gpaw-20.1.0/lib/python3.8/site-packages/gpaw-20.1.0-py3.8-linux-x86_64.egg/gpaw/calculator.py", line 726, in initialize
rank=19 L18:     xc.initialize(self.density, self.hamiltonian, self.wfs,
rank=19 L19:   File "/uls/7/gpaw-20.1.0/lib/python3.8/site-packages/gpaw-20.1.0-py3.8-linux-x86_64.egg/gpaw/xc/libvdwxc.py", line 414, in initialize
rank=19 L20:     raise ValueError('You are using libvdwxc with only '
rank=19 L21: ValueError: You are using libvdwxc with only 4 out of 32 available cores in a non-small calculation (80 x 64 x 320 points).  This is not a crime but is likely silly and therefore triggers an error.  Please use parallel={'augment_grids': True} or complain to the developers.  You can also disable this error by passing accept_partial_decomposition=True to the libvdwxc functional object, but be careful to use good domain decomposition.
GPAW CLEANUP (node 19): <class 'ValueError'> occurred.  Calling MPI_Abort!
rank=26 L00: Traceback (most recent call last):
rank=26 L01:   File "./job.py", line 20, in <module>
rank=26 L02:     relax = LBFGS(atoms=atoms, logfile='final_opt.log', trajectory='final_opt.traj')
rank=26 L03:   File "/uls/7/gpaw-20.1.0/lib/python3.8/site-packages/ase-3.20.1-py3.8.egg/ase/optimize/lbfgs.py", line 65, in __init__
rank=26 L04:     Optimizer.__init__(self, atoms, restart, logfile, trajectory, master,
rank=26 L05:   File "/uls/7/gpaw-20.1.0/lib/python3.8/site-packages/ase-3.20.1-py3.8.egg/ase/optimize/optimize.py", line 240, in __init__
rank=26 L06:     self.set_force_consistent()
rank=26 L07:   File "/uls/7/gpaw-20.1.0/lib/python3.8/site-packages/ase-3.20.1-py3.8.egg/ase/optimize/optimize.py", line 324, in set_force_consistent
rank=26 L08:     self.atoms.get_potential_energy(force_consistent=True)
rank=26 L09:   File "/uls/7/gpaw-20.1.0/lib/python3.8/site-packages/ase-3.20.1-py3.8.egg/ase/atoms.py", line 730, in get_potential_energy
rank=26 L10:     energy = self._calc.get_potential_energy(
rank=26 L11:   File "/uls/7/gpaw-20.1.0/lib/python3.8/site-packages/ase-3.20.1-py3.8.egg/ase/calculators/calculator.py", line 682, in get_potential_energy
rank=26 L12:     energy = self.get_property('energy', atoms)
rank=26 L13:   File "/uls/7/gpaw-20.1.0/lib/python3.8/site-packages/ase-3.20.1-py3.8.egg/ase/calculators/calculator.py", line 738, in get_property
rank=26 L14:     self.calculate(atoms, [name], system_changes)
rank=26 L15:   File "/uls/7/gpaw-20.1.0/lib/python3.8/site-packages/gpaw-20.1.0-py3.8-linux-x86_64.egg/gpaw/calculator.py", line 288, in calculate
rank=26 L16:     self.initialize(atoms)
rank=26 L17:   File "/uls/7/gpaw-20.1.0/lib/python3.8/site-packages/gpaw-20.1.0-py3.8-linux-x86_64.egg/gpaw/calculator.py", line 726, in initialize
rank=26 L18:     xc.initialize(self.density, self.hamiltonian, self.wfs,
rank=26 L19:   File "/uls/7/gpaw-20.1.0/lib/python3.8/site-packages/gpaw-20.1.0-py3.8-linux-x86_64.egg/gpaw/xc/libvdwxc.py", line 414, in initialize
rank=26 L20:     raise ValueError('You are using libvdwxc with only '
rank=26 L21: ValueError: You are using libvdwxc with only 4 out of 32 available cores in a non-small calculation (80 x 64 x 320 points).  This is not a crime but is likely silly and therefore triggers an error.  Please use parallel={'augment_grids': True} or complain to the developers.  You can also disable this error by passing accept_partial_decomposition=True to the libvdwxc functional object, but be careful to use good domain decomposition.
GPAW CLEANUP (node 26): <class 'ValueError'> occurred.  Calling MPI_Abort!
rank=17 L00: Traceback (most recent call last):
rank=17 L01:   File "./job.py", line 20, in <module>
rank=17 L02:     relax = LBFGS(atoms=atoms, logfile='final_opt.log', trajectory='final_opt.traj')
rank=17 L03:   File "/uls/7/gpaw-20.1.0/lib/python3.8/site-packages/ase-3.20.1-py3.8.egg/ase/optimize/lbfgs.py", line 65, in __init__
rank=17 L04:     Optimizer.__init__(self, atoms, restart, logfile, trajectory, master,
rank=17 L05:   File "/uls/7/gpaw-20.1.0/lib/python3.8/site-packages/ase-3.20.1-py3.8.egg/ase/optimize/optimize.py", line 240, in __init__
rank=17 L06:     self.set_force_consistent()
rank=17 L07:   File "/uls/7/gpaw-20.1.0/lib/python3.8/site-packages/ase-3.20.1-py3.8.egg/ase/optimize/optimize.py", line 324, in set_force_consistent
rank=17 L08:     self.atoms.get_potential_energy(force_consistent=True)
rank=17 L09:   File "/uls/7/gpaw-20.1.0/lib/python3.8/site-packages/ase-3.20.1-py3.8.egg/ase/atoms.py", line 730, in get_potential_energy
rank=17 L10:     energy = self._calc.get_potential_energy(
rank=17 L11:   File "/uls/7/gpaw-20.1.0/lib/python3.8/site-packages/ase-3.20.1-py3.8.egg/ase/calculators/calculator.py", line 682, in get_potential_energy
rank=17 L12:     energy = self.get_property('energy', atoms)
rank=17 L13:   File "/uls/7/gpaw-20.1.0/lib/python3.8/site-packages/ase-3.20.1-py3.8.egg/ase/calculators/calculator.py", line 738, in get_property
rank=17 L14:     self.calculate(atoms, [name], system_changes)
rank=17 L15:   File "/uls/7/gpaw-20.1.0/lib/python3.8/site-packages/gpaw-20.1.0-py3.8-linux-x86_64.egg/gpaw/calculator.py", line 288, in calculate
rank=17 L16:     self.initialize(atoms)
rank=17 L17:   File "/uls/7/gpaw-20.1.0/lib/python3.8/site-packages/gpaw-20.1.0-py3.8-linux-x86_64.egg/gpaw/calculator.py", line 726, in initialize
rank=17 L18:     xc.initialize(self.density, self.hamiltonian, self.wfs,
rank=17 L19:   File "/uls/7/gpaw-20.1.0/lib/python3.8/site-packages/gpaw-20.1.0-py3.8-linux-x86_64.egg/gpaw/xc/libvdwxc.py", line 414, in initialize
rank=17 L20:     raise ValueError('You are using libvdwxc with only '
rank=17 L21: ValueError: You are using libvdwxc with only 4 out of 32 available cores in a non-small calculation (80 x 64 x 320 points).  This is not a crime but is likely silly and therefore triggers an error.  Please use parallel={'augment_grids': True} or complain to the developers.  You can also disable this error by passing accept_partial_decomposition=True to the libvdwxc functional object, but be careful to use good domain decomposition.
GPAW CLEANUP (node 17): <class 'ValueError'> occurred.  Calling MPI_Abort!
rank=23 L00: Traceback (most recent call last):
rank=23 L01:   File "./job.py", line 20, in <module>
rank=23 L02:     relax = LBFGS(atoms=atoms, logfile='final_opt.log', trajectory='final_opt.traj')
rank=23 L03:   File "/uls/7/gpaw-20.1.0/lib/python3.8/site-packages/ase-3.20.1-py3.8.egg/ase/optimize/lbfgs.py", line 65, in __init__
rank=23 L04:     Optimizer.__init__(self, atoms, restart, logfile, trajectory, master,
rank=23 L05:   File "/uls/7/gpaw-20.1.0/lib/python3.8/site-packages/ase-3.20.1-py3.8.egg/ase/optimize/optimize.py", line 240, in __init__
rank=23 L06:     self.set_force_consistent()
rank=23 L07:   File "/uls/7/gpaw-20.1.0/lib/python3.8/site-packages/ase-3.20.1-py3.8.egg/ase/optimize/optimize.py", line 324, in set_force_consistent
rank=23 L08:     self.atoms.get_potential_energy(force_consistent=True)
rank=23 L09:   File "/uls/7/gpaw-20.1.0/lib/python3.8/site-packages/ase-3.20.1-py3.8.egg/ase/atoms.py", line 730, in get_potential_energy
rank=23 L10:     energy = self._calc.get_potential_energy(
rank=23 L11:   File "/uls/7/gpaw-20.1.0/lib/python3.8/site-packages/ase-3.20.1-py3.8.egg/ase/calculators/calculator.py", line 682, in get_potential_energy
rank=23 L12:     energy = self.get_property('energy', atoms)
rank=23 L13:   File "/uls/7/gpaw-20.1.0/lib/python3.8/site-packages/ase-3.20.1-py3.8.egg/ase/calculators/calculator.py", line 738, in get_property
rank=23 L14:     self.calculate(atoms, [name], system_changes)
rank=23 L15:   File "/uls/7/gpaw-20.1.0/lib/python3.8/site-packages/gpaw-20.1.0-py3.8-linux-x86_64.egg/gpaw/calculator.py", line 288, in calculate
rank=23 L16:     self.initialize(atoms)
rank=23 L17:   File "/uls/7/gpaw-20.1.0/lib/python3.8/site-packages/gpaw-20.1.0-py3.8-linux-x86_64.egg/gpaw/calculator.py", line 726, in initialize
rank=23 L18:     xc.initialize(self.density, self.hamiltonian, self.wfs,
rank=23 L19:   File "/uls/7/gpaw-20.1.0/lib/python3.8/site-packages/gpaw-20.1.0-py3.8-linux-x86_64.egg/gpaw/xc/libvdwxc.py", line 414, in initialize
rank=23 L20:     raise ValueError('You are using libvdwxc with only '
rank=23 L21: ValueError: You are using libvdwxc with only 4 out of 32 available cores in a non-small calculation (80 x 64 x 320 points).  This is not a crime but is likely silly and therefore triggers an error.  Please use parallel={'augment_grids': True} or complain to the developers.  You can also disable this error by passing accept_partial_decomposition=True to the libvdwxc functional object, but be careful to use good domain decomposition.
GPAW CLEANUP (node 23): <class 'ValueError'> occurred.  Calling MPI_Abort!
rank=31 L00: Traceback (most recent call last):
rank=31 L01:   File "./job.py", line 20, in <module>
rank=31 L02:     relax = LBFGS(atoms=atoms, logfile='final_opt.log', trajectory='final_opt.traj')
rank=31 L03:   File "/uls/7/gpaw-20.1.0/lib/python3.8/site-packages/ase-3.20.1-py3.8.egg/ase/optimize/lbfgs.py", line 65, in __init__
rank=31 L04:     Optimizer.__init__(self, atoms, restart, logfile, trajectory, master,
rank=31 L05:   File "/uls/7/gpaw-20.1.0/lib/python3.8/site-packages/ase-3.20.1-py3.8.egg/ase/optimize/optimize.py", line 240, in __init__
rank=31 L06:     self.set_force_consistent()
rank=31 L07:   File "/uls/7/gpaw-20.1.0/lib/python3.8/site-packages/ase-3.20.1-py3.8.egg/ase/optimize/optimize.py", line 324, in set_force_consistent
rank=31 L08:     self.atoms.get_potential_energy(force_consistent=True)
rank=31 L09:   File "/uls/7/gpaw-20.1.0/lib/python3.8/site-packages/ase-3.20.1-py3.8.egg/ase/atoms.py", line 730, in get_potential_energy
rank=31 L10:     energy = self._calc.get_potential_energy(
rank=31 L11:   File "/uls/7/gpaw-20.1.0/lib/python3.8/site-packages/ase-3.20.1-py3.8.egg/ase/calculators/calculator.py", line 682, in get_potential_energy
rank=31 L12:     energy = self.get_property('energy', atoms)
rank=31 L13:   File "/uls/7/gpaw-20.1.0/lib/python3.8/site-packages/ase-3.20.1-py3.8.egg/ase/calculators/calculator.py", line 738, in get_property
rank=31 L14:     self.calculate(atoms, [name], system_changes)
rank=31 L15:   File "/uls/7/gpaw-20.1.0/lib/python3.8/site-packages/gpaw-20.1.0-py3.8-linux-x86_64.egg/gpaw/calculator.py", line 288, in calculate
rank=31 L16:     self.initialize(atoms)
rank=31 L17:   File "/uls/7/gpaw-20.1.0/lib/python3.8/site-packages/gpaw-20.1.0-py3.8-linux-x86_64.egg/gpaw/calculator.py", line 726, in initialize
rank=31 L18:     xc.initialize(self.density, self.hamiltonian, self.wfs,
rank=31 L19:   File "/uls/7/gpaw-20.1.0/lib/python3.8/site-packages/gpaw-20.1.0-py3.8-linux-x86_64.egg/gpaw/xc/libvdwxc.py", line 414, in initialize
rank=31 L20:     raise ValueError('You are using libvdwxc with only '
rank=31 L21: ValueError: You are using libvdwxc with only 4 out of 32 available cores in a non-small calculation (80 x 64 x 320 points).  This is not a crime but is likely silly and therefore triggers an error.  Please use parallel={'augment_grids': True} or complain to the developers.  You can also disable this error by passing accept_partial_decomposition=True to the libvdwxc functional object, but be careful to use good domain decomposition.
GPAW CLEANUP (node 31): <class 'ValueError'> occurred.  Calling MPI_Abort!
rank=03 L00: Traceback (most recent call last):
rank=03 L01:   File "./job.py", line 20, in <module>
rank=03 L02:     relax = LBFGS(atoms=atoms, logfile='final_opt.log', trajectory='final_opt.traj')
rank=03 L03:   File "/uls/7/gpaw-20.1.0/lib/python3.8/site-packages/ase-3.20.1-py3.8.egg/ase/optimize/lbfgs.py", line 65, in __init__
rank=03 L04:     Optimizer.__init__(self, atoms, restart, logfile, trajectory, master,
rank=03 L05:   File "/uls/7/gpaw-20.1.0/lib/python3.8/site-packages/ase-3.20.1-py3.8.egg/ase/optimize/optimize.py", line 240, in __init__
rank=03 L06:     self.set_force_consistent()
rank=03 L07:   File "/uls/7/gpaw-20.1.0/lib/python3.8/site-packages/ase-3.20.1-py3.8.egg/ase/optimize/optimize.py", line 324, in set_force_consistent
rank=03 L08:     self.atoms.get_potential_energy(force_consistent=True)
rank=03 L09:   File "/uls/7/gpaw-20.1.0/lib/python3.8/site-packages/ase-3.20.1-py3.8.egg/ase/atoms.py", line 730, in get_potential_energy
rank=03 L10:     energy = self._calc.get_potential_energy(
rank=03 L11:   File "/uls/7/gpaw-20.1.0/lib/python3.8/site-packages/ase-3.20.1-py3.8.egg/ase/calculators/calculator.py", line 682, in get_potential_energy
rank=03 L12:     energy = self.get_property('energy', atoms)
rank=03 L13:   File "/uls/7/gpaw-20.1.0/lib/python3.8/site-packages/ase-3.20.1-py3.8.egg/ase/calculators/calculator.py", line 738, in get_property
rank=03 L14:     self.calculate(atoms, [name], system_changes)
rank=03 L15:   File "/uls/7/gpaw-20.1.0/lib/python3.8/site-packages/gpaw-20.1.0-py3.8-linux-x86_64.egg/gpaw/calculator.py", line 288, in calculate
rank=03 L16:     self.initialize(atoms)
rank=03 L17:   File "/uls/7/gpaw-20.1.0/lib/python3.8/site-packages/gpaw-20.1.0-py3.8-linux-x86_64.egg/gpaw/calculator.py", line 726, in initialize
rank=03 L18:     xc.initialize(self.density, self.hamiltonian, self.wfs,
rank=03 L19:   File "/uls/7/gpaw-20.1.0/lib/python3.8/site-packages/gpaw-20.1.0-py3.8-linux-x86_64.egg/gpaw/xc/libvdwxc.py", line 414, in initialize
rank=03 L20:     raise ValueError('You are using libvdwxc with only '
rank=03 L21: ValueError: You are using libvdwxc with only 4 out of 32 available cores in a non-small calculation (80 x 64 x 320 points).  This is not a crime but is likely silly and therefore triggers an error.  Please use parallel={'augment_grids': True} or complain to the developers.  You can also disable this error by passing accept_partial_decomposition=True to the libvdwxc functional object, but be careful to use good domain decomposition.
GPAW CLEANUP (node 3): <class 'ValueError'> occurred.  Calling MPI_Abort!
rank=09 L00: Traceback (most recent call last):
rank=09 L01:   File "./job.py", line 20, in <module>
rank=09 L02:     relax = LBFGS(atoms=atoms, logfile='final_opt.log', trajectory='final_opt.traj')
rank=09 L03:   File "/uls/7/gpaw-20.1.0/lib/python3.8/site-packages/ase-3.20.1-py3.8.egg/ase/optimize/lbfgs.py", line 65, in __init__
rank=09 L04:     Optimizer.__init__(self, atoms, restart, logfile, trajectory, master,
rank=09 L05:   File "/uls/7/gpaw-20.1.0/lib/python3.8/site-packages/ase-3.20.1-py3.8.egg/ase/optimize/optimize.py", line 240, in __init__
rank=09 L06:     self.set_force_consistent()
rank=09 L07:   File "/uls/7/gpaw-20.1.0/lib/python3.8/site-packages/ase-3.20.1-py3.8.egg/ase/optimize/optimize.py", line 324, in set_force_consistent
rank=09 L08:     self.atoms.get_potential_energy(force_consistent=True)
rank=09 L09:   File "/uls/7/gpaw-20.1.0/lib/python3.8/site-packages/ase-3.20.1-py3.8.egg/ase/atoms.py", line 730, in get_potential_energy
rank=09 L10:     energy = self._calc.get_potential_energy(
rank=09 L11:   File "/uls/7/gpaw-20.1.0/lib/python3.8/site-packages/ase-3.20.1-py3.8.egg/ase/calculators/calculator.py", line 682, in get_potential_energy
rank=09 L12:     energy = self.get_property('energy', atoms)
rank=09 L13:   File "/uls/7/gpaw-20.1.0/lib/python3.8/site-packages/ase-3.20.1-py3.8.egg/ase/calculators/calculator.py", line 738, in get_property
rank=09 L14:     self.calculate(atoms, [name], system_changes)
rank=09 L15:   File "/uls/7/gpaw-20.1.0/lib/python3.8/site-packages/gpaw-20.1.0-py3.8-linux-x86_64.egg/gpaw/calculator.py", line 288, in calculate
rank=09 L16:     self.initialize(atoms)
rank=09 L17:   File "/uls/7/gpaw-20.1.0/lib/python3.8/site-packages/gpaw-20.1.0-py3.8-linux-x86_64.egg/gpaw/calculator.py", line 726, in initialize
rank=09 L18:     xc.initialize(self.density, self.hamiltonian, self.wfs,
rank=09 L19:   File "/uls/7/gpaw-20.1.0/lib/python3.8/site-packages/gpaw-20.1.0-py3.8-linux-x86_64.egg/gpaw/xc/libvdwxc.py", line 414, in initialize
rank=09 L20:     raise ValueError('You are using libvdwxc with only '
rank=09 L21: ValueError: You are using libvdwxc with only 4 out of 32 available cores in a non-small calculation (80 x 64 x 320 points).  This is not a crime but is likely silly and therefore triggers an error.  Please use parallel={'augment_grids': True} or complain to the developers.  You can also disable this error by passing accept_partial_decomposition=True to the libvdwxc functional object, but be careful to use good domain decomposition.
GPAW CLEANUP (node 9): <class 'ValueError'> occurred.  Calling MPI_Abort!
rank=11 L00: Traceback (most recent call last):
rank=11 L01:   File "./job.py", line 20, in <module>
rank=11 L02:     relax = LBFGS(atoms=atoms, logfile='final_opt.log', trajectory='final_opt.traj')
rank=11 L03:   File "/uls/7/gpaw-20.1.0/lib/python3.8/site-packages/ase-3.20.1-py3.8.egg/ase/optimize/lbfgs.py", line 65, in __init__
rank=11 L04:     Optimizer.__init__(self, atoms, restart, logfile, trajectory, master,
rank=11 L05:   File "/uls/7/gpaw-20.1.0/lib/python3.8/site-packages/ase-3.20.1-py3.8.egg/ase/optimize/optimize.py", line 240, in __init__
rank=11 L06:     self.set_force_consistent()
rank=11 L07:   File "/uls/7/gpaw-20.1.0/lib/python3.8/site-packages/ase-3.20.1-py3.8.egg/ase/optimize/optimize.py", line 324, in set_force_consistent
rank=11 L08:     self.atoms.get_potential_energy(force_consistent=True)
rank=11 L09:   File "/uls/7/gpaw-20.1.0/lib/python3.8/site-packages/ase-3.20.1-py3.8.egg/ase/atoms.py", line 730, in get_potential_energy
rank=11 L10:     energy = self._calc.get_potential_energy(
rank=11 L11:   File "/uls/7/gpaw-20.1.0/lib/python3.8/site-packages/ase-3.20.1-py3.8.egg/ase/calculators/calculator.py", line 682, in get_potential_energy
rank=11 L12:     energy = self.get_property('energy', atoms)
rank=11 L13:   File "/uls/7/gpaw-20.1.0/lib/python3.8/site-packages/ase-3.20.1-py3.8.egg/ase/calculators/calculator.py", line 738, in get_property
rank=11 L14:     self.calculate(atoms, [name], system_changes)
rank=11 L15:   File "/uls/7/gpaw-20.1.0/lib/python3.8/site-packages/gpaw-20.1.0-py3.8-linux-x86_64.egg/gpaw/calculator.py", line 288, in calculate
rank=11 L16:     self.initialize(atoms)
rank=11 L17:   File "/uls/7/gpaw-20.1.0/lib/python3.8/site-packages/gpaw-20.1.0-py3.8-linux-x86_64.egg/gpaw/calculator.py", line 726, in initialize
rank=11 L18:     xc.initialize(self.density, self.hamiltonian, self.wfs,
rank=11 L19:   File "/uls/7/gpaw-20.1.0/lib/python3.8/site-packages/gpaw-20.1.0-py3.8-linux-x86_64.egg/gpaw/xc/libvdwxc.py", line 414, in initialize
rank=11 L20:     raise ValueError('You are using libvdwxc with only '
rank=11 L21: ValueError: You are using libvdwxc with only 4 out of 32 available cores in a non-small calculation (80 x 64 x 320 points).  This is not a crime but is likely silly and therefore triggers an error.  Please use parallel={'augment_grids': True} or complain to the developers.  You can also disable this error by passing accept_partial_decomposition=True to the libvdwxc functional object, but be careful to use good domain decomposition.
GPAW CLEANUP (node 11): <class 'ValueError'> occurred.  Calling MPI_Abort!
rank=07 L00: Traceback (most recent call last):
rank=07 L01:   File "./job.py", line 20, in <module>
rank=07 L02:     relax = LBFGS(atoms=atoms, logfile='final_opt.log', trajectory='final_opt.traj')
rank=07 L03:   File "/uls/7/gpaw-20.1.0/lib/python3.8/site-packages/ase-3.20.1-py3.8.egg/ase/optimize/lbfgs.py", line 65, in __init__
rank=07 L04:     Optimizer.__init__(self, atoms, restart, logfile, trajectory, master,
rank=07 L05:   File "/uls/7/gpaw-20.1.0/lib/python3.8/site-packages/ase-3.20.1-py3.8.egg/ase/optimize/optimize.py", line 240, in __init__
rank=07 L06:     self.set_force_consistent()
rank=07 L07:   File "/uls/7/gpaw-20.1.0/lib/python3.8/site-packages/ase-3.20.1-py3.8.egg/ase/optimize/optimize.py", line 324, in set_force_consistent
rank=07 L08:     self.atoms.get_potential_energy(force_consistent=True)
rank=07 L09:   File "/uls/7/gpaw-20.1.0/lib/python3.8/site-packages/ase-3.20.1-py3.8.egg/ase/atoms.py", line 730, in get_potential_energy
rank=07 L10:     energy = self._calc.get_potential_energy(
rank=07 L11:   File "/uls/7/gpaw-20.1.0/lib/python3.8/site-packages/ase-3.20.1-py3.8.egg/ase/calculators/calculator.py", line 682, in get_potential_energy
rank=07 L12:     energy = self.get_property('energy', atoms)
rank=07 L13:   File "/uls/7/gpaw-20.1.0/lib/python3.8/site-packages/ase-3.20.1-py3.8.egg/ase/calculators/calculator.py", line 738, in get_property
rank=07 L14:     self.calculate(atoms, [name], system_changes)
rank=07 L15:   File "/uls/7/gpaw-20.1.0/lib/python3.8/site-packages/gpaw-20.1.0-py3.8-linux-x86_64.egg/gpaw/calculator.py", line 288, in calculate
rank=07 L16:     self.initialize(atoms)
rank=07 L17:   File "/uls/7/gpaw-20.1.0/lib/python3.8/site-packages/gpaw-20.1.0-py3.8-linux-x86_64.egg/gpaw/calculator.py", line 726, in initialize
rank=07 L18:     xc.initialize(self.density, self.hamiltonian, self.wfs,
rank=07 L19:   File "/uls/7/gpaw-20.1.0/lib/python3.8/site-packages/gpaw-20.1.0-py3.8-linux-x86_64.egg/gpaw/xc/libvdwxc.py", line 414, in initialize
rank=07 L20:     raise ValueError('You are using libvdwxc with only '
rank=07 L21: ValueError: You are using libvdwxc with only 4 out of 32 available cores in a non-small calculation (80 x 64 x 320 points).  This is not a crime but is likely silly and therefore triggers an error.  Please use parallel={'augment_grids': True} or complain to the developers.  You can also disable this error by passing accept_partial_decomposition=True to the libvdwxc functional object, but be careful to use good domain decomposition.
GPAW CLEANUP (node 7): <class 'ValueError'> occurred.  Calling MPI_Abort!
rank=13 L00: Traceback (most recent call last):
rank=13 L01:   File "./job.py", line 20, in <module>
rank=13 L02:     relax = LBFGS(atoms=atoms, logfile='final_opt.log', trajectory='final_opt.traj')
rank=13 L03:   File "/uls/7/gpaw-20.1.0/lib/python3.8/site-packages/ase-3.20.1-py3.8.egg/ase/optimize/lbfgs.py", line 65, in __init__
rank=13 L04:     Optimizer.__init__(self, atoms, restart, logfile, trajectory, master,
rank=13 L05:   File "/uls/7/gpaw-20.1.0/lib/python3.8/site-packages/ase-3.20.1-py3.8.egg/ase/optimize/optimize.py", line 240, in __init__
rank=13 L06:     self.set_force_consistent()
rank=13 L07:   File "/uls/7/gpaw-20.1.0/lib/python3.8/site-packages/ase-3.20.1-py3.8.egg/ase/optimize/optimize.py", line 324, in set_force_consistent
rank=13 L08:     self.atoms.get_potential_energy(force_consistent=True)
rank=13 L09:   File "/uls/7/gpaw-20.1.0/lib/python3.8/site-packages/ase-3.20.1-py3.8.egg/ase/atoms.py", line 730, in get_potential_energy
rank=13 L10:     energy = self._calc.get_potential_energy(
rank=13 L11:   File "/uls/7/gpaw-20.1.0/lib/python3.8/site-packages/ase-3.20.1-py3.8.egg/ase/calculators/calculator.py", line 682, in get_potential_energy
rank=13 L12:     energy = self.get_property('energy', atoms)
rank=13 L13:   File "/uls/7/gpaw-20.1.0/lib/python3.8/site-packages/ase-3.20.1-py3.8.egg/ase/calculators/calculator.py", line 738, in get_property
rank=13 L14:     self.calculate(atoms, [name], system_changes)
rank=13 L15:   File "/uls/7/gpaw-20.1.0/lib/python3.8/site-packages/gpaw-20.1.0-py3.8-linux-x86_64.egg/gpaw/calculator.py", line 288, in calculate
rank=13 L16:     self.initialize(atoms)
rank=13 L17:   File "/uls/7/gpaw-20.1.0/lib/python3.8/site-packages/gpaw-20.1.0-py3.8-linux-x86_64.egg/gpaw/calculator.py", line 726, in initialize
rank=13 L18:     xc.initialize(self.density, self.hamiltonian, self.wfs,
rank=13 L19:   File "/uls/7/gpaw-20.1.0/lib/python3.8/site-packages/gpaw-20.1.0-py3.8-linux-x86_64.egg/gpaw/xc/libvdwxc.py", line 414, in initialize
rank=13 L20:     raise ValueError('You are using libvdwxc with only '
rank=13 L21: ValueError: You are using libvdwxc with only 4 out of 32 available cores in a non-small calculation (80 x 64 x 320 points).  This is not a crime but is likely silly and therefore triggers an error.  Please use parallel={'augment_grids': True} or complain to the developers.  You can also disable this error by passing accept_partial_decomposition=True to the libvdwxc functional object, but be careful to use good domain decomposition.
GPAW CLEANUP (node 13): <class 'ValueError'> occurred.  Calling MPI_Abort!
rank=05 L00: Traceback (most recent call last):
rank=05 L01:   File "./job.py", line 20, in <module>
rank=05 L02:     relax = LBFGS(atoms=atoms, logfile='final_opt.log', trajectory='final_opt.traj')
rank=05 L03:   File "/uls/7/gpaw-20.1.0/lib/python3.8/site-packages/ase-3.20.1-py3.8.egg/ase/optimize/lbfgs.py", line 65, in __init__
rank=05 L04:     Optimizer.__init__(self, atoms, restart, logfile, trajectory, master,
rank=05 L05:   File "/uls/7/gpaw-20.1.0/lib/python3.8/site-packages/ase-3.20.1-py3.8.egg/ase/optimize/optimize.py", line 240, in __init__
rank=05 L06:     self.set_force_consistent()
rank=05 L07:   File "/uls/7/gpaw-20.1.0/lib/python3.8/site-packages/ase-3.20.1-py3.8.egg/ase/optimize/optimize.py", line 324, in set_force_consistent
rank=05 L08:     self.atoms.get_potential_energy(force_consistent=True)
rank=05 L09:   File "/uls/7/gpaw-20.1.0/lib/python3.8/site-packages/ase-3.20.1-py3.8.egg/ase/atoms.py", line 730, in get_potential_energy
rank=05 L10:     energy = self._calc.get_potential_energy(
rank=05 L11:   File "/uls/7/gpaw-20.1.0/lib/python3.8/site-packages/ase-3.20.1-py3.8.egg/ase/calculators/calculator.py", line 682, in get_potential_energy
rank=05 L12:     energy = self.get_property('energy', atoms)
rank=05 L13:   File "/uls/7/gpaw-20.1.0/lib/python3.8/site-packages/ase-3.20.1-py3.8.egg/ase/calculators/calculator.py", line 738, in get_property
rank=05 L14:     self.calculate(atoms, [name], system_changes)
rank=05 L15:   File "/uls/7/gpaw-20.1.0/lib/python3.8/site-packages/gpaw-20.1.0-py3.8-linux-x86_64.egg/gpaw/calculator.py", line 288, in calculate
rank=05 L16:     self.initialize(atoms)
rank=05 L17:   File "/uls/7/gpaw-20.1.0/lib/python3.8/site-packages/gpaw-20.1.0-py3.8-linux-x86_64.egg/gpaw/calculator.py", line 726, in initialize
rank=05 L18:     xc.initialize(self.density, self.hamiltonian, self.wfs,
rank=05 L19:   File "/uls/7/gpaw-20.1.0/lib/python3.8/site-packages/gpaw-20.1.0-py3.8-linux-x86_64.egg/gpaw/xc/libvdwxc.py", line 414, in initialize
rank=05 L20:     raise ValueError('You are using libvdwxc with only '
rank=05 L21: ValueError: You are using libvdwxc with only 4 out of 32 available cores in a non-small calculation (80 x 64 x 320 points).  This is not a crime but is likely silly and therefore triggers an error.  Please use parallel={'augment_grids': True} or complain to the developers.  You can also disable this error by passing accept_partial_decomposition=True to the libvdwxc functional object, but be careful to use good domain decomposition.
GPAW CLEANUP (node 5): <class 'ValueError'> occurred.  Calling MPI_Abort!
rank=15 L00: Traceback (most recent call last):
rank=15 L01:   File "./job.py", line 20, in <module>
rank=15 L02:     relax = LBFGS(atoms=atoms, logfile='final_opt.log', trajectory='final_opt.traj')
rank=15 L03:   File "/uls/7/gpaw-20.1.0/lib/python3.8/site-packages/ase-3.20.1-py3.8.egg/ase/optimize/lbfgs.py", line 65, in __init__
rank=15 L04:     Optimizer.__init__(self, atoms, restart, logfile, trajectory, master,
rank=15 L05:   File "/uls/7/gpaw-20.1.0/lib/python3.8/site-packages/ase-3.20.1-py3.8.egg/ase/optimize/optimize.py", line 240, in __init__
rank=15 L06:     self.set_force_consistent()
rank=15 L07:   File "/uls/7/gpaw-20.1.0/lib/python3.8/site-packages/ase-3.20.1-py3.8.egg/ase/optimize/optimize.py", line 324, in set_force_consistent
rank=15 L08:     self.atoms.get_potential_energy(force_consistent=True)
rank=15 L09:   File "/uls/7/gpaw-20.1.0/lib/python3.8/site-packages/ase-3.20.1-py3.8.egg/ase/atoms.py", line 730, in get_potential_energy
rank=15 L10:     energy = self._calc.get_potential_energy(
rank=15 L11:   File "/uls/7/gpaw-20.1.0/lib/python3.8/site-packages/ase-3.20.1-py3.8.egg/ase/calculators/calculator.py", line 682, in get_potential_energy
rank=15 L12:     energy = self.get_property('energy', atoms)
rank=15 L13:   File "/uls/7/gpaw-20.1.0/lib/python3.8/site-packages/ase-3.20.1-py3.8.egg/ase/calculators/calculator.py", line 738, in get_property
rank=15 L14:     self.calculate(atoms, [name], system_changes)
rank=15 L15:   File "/uls/7/gpaw-20.1.0/lib/python3.8/site-packages/gpaw-20.1.0-py3.8-linux-x86_64.egg/gpaw/calculator.py", line 288, in calculate
rank=15 L16:     self.initialize(atoms)
rank=15 L17:   File "/uls/7/gpaw-20.1.0/lib/python3.8/site-packages/gpaw-20.1.0-py3.8-linux-x86_64.egg/gpaw/calculator.py", line 726, in initialize
rank=15 L18:     xc.initialize(self.density, self.hamiltonian, self.wfs,
rank=15 L19:   File "/uls/7/gpaw-20.1.0/lib/python3.8/site-packages/gpaw-20.1.0-py3.8-linux-x86_64.egg/gpaw/xc/libvdwxc.py", line 414, in initialize
rank=15 L20:     raise ValueError('You are using libvdwxc with only '
rank=15 L21: ValueError: You are using libvdwxc with only 4 out of 32 available cores in a non-small calculation (80 x 64 x 320 points).  This is not a crime but is likely silly and therefore triggers an error.  Please use parallel={'augment_grids': True} or complain to the developers.  You can also disable this error by passing accept_partial_decomposition=True to the libvdwxc functional object, but be careful to use good domain decomposition.
GPAW CLEANUP (node 15): <class 'ValueError'> occurred.  Calling MPI_Abort!
--------------------------------------------------------------------------
MPI_ABORT was invoked on rank 0 in communicator MPI_COMM_WORLD
with errorcode 42.

NOTE: invoking MPI_ABORT causes Open MPI to kill all MPI processes.
You may or may not see output from other processes, depending on
exactly when Open MPI kills them.
--------------------------------------------------------------------------
[n716006:12633] 25 more processes have sent help message help-mpi-api.txt / mpi-abort
[n716006:12633] Set MCA parameter "orte_base_help_aggregate" to 0 to see all help / error messages
